Workbook
Name AvailableCDPs: 'Available CDPs'!$A$4:$A$11
Name Comparison_CDP1: Comparison!$B$8
Name Comparison_CDP2: Comparison!$B$9
Name Summary_CDP: Summary!$B$8
Name WACC: 0.075

Sheet Disclaimer
B2: Disclaimer
B4: This generation outcomes workbook contains data provided by or collected from third parties,
B5: and conclusions, opinions, assumptions or forecasts that are based on that data.
B7: AEMO has made every effort to ensure the quality of the information in this workbook but cannot guarantee
B8: that the information, forecasts and assumptions in it are accurate, complete or appropriate for your
B9: circumstances. This generation outcomes workbook does not include all of the information that an investor,
B10: participant or potential participant in the electricity or gas market might require, and does not amount to a
B11: recommendation of any investment.
B13: Anyone proposing to use the information in this workbook should independently verify and check its
B14: accuracy, completeness and suitability for purpose, and obtain independent and specific advice from
B15: appropriate experts.
B17: This dataset or the information in it may be subsequently updated or amended. This work does
... B28: or in respect of a person’s use of the information in this workbook.

Sheet Index
B2: 2022 ISP Results Workbook
B4: Version History
B5: Version Number | C5: Description
B6: v1.0 | C6: Initial release
B7: v1.1 | C7: Added regional import and export data
B8: v1.2 | C8: Minor fixes
B10: About
B11: This workbook presents generation and cost data for the Draft 2022 ISP. For a complete description of the scenarios and sensitivities, please see the Draft 2022 ISP report.
B13: Index Table
B14: Tab Name | C14: Content Description
B15: CDPs | C15: Description of Candidate Development Pathways
B16: Summary | C16: Summary (calculated) for a selected case
B17: Comparison | C17: Comparison (calculated) between two selected cases
B18: REZ Generation Capacity | C18: Installed capacity by REZ and technology for all cases
B19: REZ Generation | C19: Annual as-generated generation by REZ and technology for all cases

Sheet CDPs
A2: Candidate Development Paths
B4: Purpose | C4: New England REZ Transmission Link | D4: Sydney Ring | E4: Marinus Link | F4: VNI West | G4: HumeLink | H4: Gladstone Grid Reinforcement
A5: CDP1 | B5: Based on Progressive Change least-cost DP | C5: Potential actionable | D5: Potential actionable
A6: CDP2 | B6: Based on Step Change least-cost DP (Progressive Change least-cost with actionable ML and VNI West) | C6: Potential actionable | D6: Potential actionable | E6: Potential actionable | F6: Potential actionable
A8: CDP3 | B8: Based on Hydrogen Superpower least-cost DP | C8: Potential actionable | D8: Potential actionable | E8: Potential actionable | F8: Potential actionable | G8: Potential actionable | H8: Potential actionable
A9: CDP4 | B9: Based on Slow Change least-cost DP (Progressive Change without actionable Sydney Ring) | C9: Potential actionable
A11: CDP5 | B11: Progressive Change least-cost DP, with Marinus Link actionable | C11: Potential actionable | D11: Potential actionable | E11: Potential actionable
A12: CDP6 | B12: Progressive Change, with VNI West actionable | C12: Potential actionable | D12: Potential actionable | F12: Potential actionable
A13: CDP7 | B13: Progressive Change, without New England REZ Transmission Link actionable | D13: Potential actionable
A14: CDP8 | B14: Step Change, with HumeLink actionable | C14: Potential actionable | D14: Potential actionable | E14: Potential actionable | F14: Potential actionable | G14: Potential actionable
A15: CDP9 | B15: No actionable projects
A16: CDP10 | B16: Progressive Change least-cost DP, with actionable Marinus Link and VNI West staged | C16: Potential actionable | D16: Potential actionable | E16: Potential actionable | F16: Stage 1 (Early Works)
A17: CDP11 | B17: Progressive Change least-cost DP, with actionable Marinus Link, VNI West staged, and actionable HumeLink | C17: Potential actionable | D17: Potential actionable | E17: Potential actionable | F17: Stage 1 (Early Works) | G17: Potential actionable
A18: CDP12 | B18: Progressive Change least-cost DP, with actionable Marinus Link, and staged VNI West and HumeLink | C18: Potential actionable | D18: Potential actionable | E18: Potential actionable | F18: Stage 1 (Early Works) | G18: Stage 1 (Early Works)
A19: CDP13 | B19: Progressive Change least-cost DP with staged VNI West and HumeLink, but with Marinus Link not available | C19: Potential actionable | D19: Potential actionable | E19: Never available | F19: Stage 1 (Early Works) | G19: Stage 1 (Early Works)
A20: Counterfactual | B20: No future network augmentation other than committed and anticipated projects/ small intra-regional augmentations/ replacement expenditure projects
A22: Refer to the summary tab for the specific timings of all augmentation options for a selected CDP.

Sheet Summary
A2: ="Case Summary - "&Summary_CDP -> Case Summary - CDP1
A3: Notes
A4: ="1. The discount rate used for calculation is "&TEXT(WACC,"0.0%") -> 1. The discount rate used for calculation is 7.5%
A5: 2. All costs exclude any additional reliability cost savings, competition benefits and early works costs. Further details on these components are provided in Appendix 6.
C7: Description:
A8: Select case | B8: CDP1 | C8: =INDEX(CDPs!$B$5:$B$20,MATCH(Summary_CDP,CDPs!$A$5:$A$20,0),1) -> Based on Progressive Change least-cost DP
A11: Discounted total system costs by year
H14: Real June 2021 dollars ($m) | I14: NPV | J14: 2023-24 | K14: 2024-25 | L14: 2025-26 | M14: 2026-27 | N14: 2027-28 | O14: 2028-29 | P14: 2029-30 | Q14: 2030-31 | R14: 2031-32 | S14: 2032-33 | T14: 2033-34 | U14: 2034-35 | V14: 2035-36 | W14: 2036-37 | X14: 2037-38 | Y14: 2038-39 | Z14: 2039-40 | AA14: 2040-41 | AB14: 2041-42 | AC14: 2042-43 | AD14: 2043-44 | AE14: 2044-45 | AF14: 2045-46 | AG14: 2046-47 | AH14: 2047-48 | AI14: 2048-49 | AJ14: 2049-50 | AK14: 2050-51
H15: Generator Capital | I15: =NPV(WACC,J15:AK15)/(1+WACC)^2 -> 191565.75 | J15: =SUMIFS(Costs!C:C,Costs!$A:$A,Summary_CDP,Costs!$B:$B,$H15)/1000 -> 1069.726 | K15: =SUMIFS(Costs!D:D,Costs!$A:$A,Summary_CDP,Costs!$B:$B,$H15)/1000 -> 2387.4603 | L15: =SUMIFS(Costs!E:E,Costs!$A:$A,Summary_CDP,Costs!$B:$B,$H15)/1000 -> 4374.2223 | M15: =SUMIFS(Costs!F:F,Costs!$A:$A,Summary_CDP,Costs!$B:$B,$H15)/1000 -> 5783.7273 | N15: =SUMIFS(Costs!G:G,Costs!$A:$A,Summary_CDP,Costs!$B:$B,$H15)/1000 -> 8224.1375 | O15: =SUMIFS(Costs!H:H,Costs!$A:$A,Summary_CDP,Costs!$B:$B,$H15)/1000 -> 9945.3866 | P15: =SUMIFS(Costs!I:I,Costs!$A:$A,Summary_CDP,Costs!$B:$B,$H15)/1000 -> 10672.807 | Q15: =SUMIFS(Costs!J:J,Costs!$A:$A,Summary_CDP,Costs!$B:$B,$H15)/1000 -> 12715.458 | R15: =SUMIFS(Costs!K:K,Costs!$A:$A,Summary_CDP,Costs!$B:$B,$H15)/1000 -> 13960.86 | S15: =SUMIFS(Costs!L:L,Costs!$A:$A,Summary_CDP,Costs!$B:$B,$H15)/1000 -> 14875.288 | T15: =SUMIFS(Costs!M:M,Costs!$A:$A,Summary_CDP,Costs!$B:$B,$H15)/1000 -> 17119.351 | U15: =SUMIFS(Costs!N:N,Costs!$A:$A,Summary_CDP,Costs!$B:$B,$H15)/1000 -> 20317.945 | V15: =SUMIFS(Costs!O:O,Costs!$A:$A,Summary_CDP,Costs!$B:$B,$H15)/1000 -> 21905.568 | W15: =SUMIFS(Costs!P:P,Costs!$A:$A,Summary_CDP,Costs!$B:$B,$H15)/1000 -> 24587.463 | X15: =SUMIFS(Costs!Q:Q,Costs!$A:$A,Summary_CDP,Costs!$B:$B,$H15)/1000 -> 27013.54 | Y15: =SUMIFS(Costs!R:R,Costs!$A:$A,Summary_CDP,Costs!$B:$B,$H15)/1000 -> 28595.843 | Z15: =SUMIFS(Costs!S:S,Costs!$A:$A,Summary_CDP,Costs!$B:$B,$H15)/1000 -> 28595.843 | AA15: =SUMIFS(Costs!T:T,Costs!$A:$A,Summary_CDP,Costs!$B:$B,$H15)/1000 -> 30564.406 | AB15: =SUMIFS(Costs!U:U,Costs!$A:$A,Summary_CDP,Costs!$B:$B,$H15)/1000 -> 35942.259 | AC15: =SUMIFS(Costs!V:V,Costs!$A:$A,Summary_CDP,Costs!$B:$B,$H15)/1000 -> 41266.37 | AD15: =SUMIFS(Costs!W:W,Costs!$A:$A,Summary_CDP,Costs!$B:$B,$H15)/1000 -> 47049.177 | AE15: =SUMIFS(Costs!X:X,Costs!$A:$A,Summary_CDP,Costs!$B:$B,$H15)/1000 -> 50669.355 | AF15: =SUMIFS(Costs!Y:Y,Costs!$A:$A,Summary_CDP,Costs!$B:$B,$H15)/1000 -> 57335.328 | AG15: =SUMIFS(Costs!Z:Z,Costs!$A:$A,Summary_CDP,Costs!$B:$B,$H15)/1000 -> 59369.294 | AH15: =SUMIFS(Costs!AA:AA,Costs!$A:$A,Summary_CDP,Costs!$B:$B,$H15)/1000 -> 61501.829 | AI15: =SUMIFS(Costs!AB:AB,Costs!$A:$A,Summary_CDP,Costs!$B:$B,$H15)/1000 -> 65960.368 | AJ15: =SUMIFS(Costs!AC:AC,Costs!$A:$A,Summary_CDP,Costs!$B:$B,$H15)/1000 -> 76833.728 | AK15: =SUMIFS(Costs!AD:AD,Costs!$A:$A,Summary_CDP,Costs!$B:$B,$H15)/1000 -> 74789.891
H16: FOM | I16: =NPV(WACC,J16:AK16)/(1+WACC)^2 -> 48709.898 | J16: =SUMIFS(Costs!C:C,Costs!$A:$A,Summary_CDP,Costs!$B:$B,$H16)/1000 -> 2860.583 | K16: =SUMIFS(Costs!D:D,Costs!$A:$A,Summary_CDP,Costs!$B:$B,$H16)/1000 -> 3037.808 | L16: =SUMIFS(Costs!E:E,Costs!$A:$A,Summary_CDP,Costs!$B:$B,$H16)/1000 -> 3923.4663 | M16: =SUMIFS(Costs!F:F,Costs!$A:$A,Summary_CDP,Costs!$B:$B,$H16)/1000 -> 3276.7732 | N16: =SUMIFS(Costs!G:G,Costs!$A:$A,Summary_CDP,Costs!$B:$B,$H16)/1000 -> 3513.7041 | O16: =SUMIFS(Costs!H:H,Costs!$A:$A,Summary_CDP,Costs!$B:$B,$H16)/1000 -> 3172.8873 | P16: =SUMIFS(Costs!I:I,Costs!$A:$A,Summary_CDP,Costs!$B:$B,$H16)/1000 -> 3122.4962 | Q16: =SUMIFS(Costs!J:J,Costs!$A:$A,Summary_CDP,Costs!$B:$B,$H16)/1000 -> 3612.853 | R16: =SUMIFS(Costs!K:K,Costs!$A:$A,Summary_CDP,Costs!$B:$B,$H16)/1000 -> 3241.5481 | S16: =SUMIFS(Costs!L:L,Costs!$A:$A,Summary_CDP,Costs!$B:$B,$H16)/1000 -> 3417.9183 | T16: =SUMIFS(Costs!M:M,Costs!$A:$A,Summary_CDP,Costs!$B:$B,$H16)/1000 -> 3789.9376 | U16: =SUMIFS(Costs!N:N,Costs!$A:$A,Summary_CDP,Costs!$B:$B,$H16)/1000 -> 4311.1304 | V16: =SUMIFS(Costs!O:O,Costs!$A:$A,Summary_CDP,Costs!$B:$B,$H16)/1000 -> 4656.6671 | W16: =SUMIFS(Costs!P:P,Costs!$A:$A,Summary_CDP,Costs!$B:$B,$H16)/1000 -> 5063.8046 | X16: =SUMIFS(Costs!Q:Q,Costs!$A:$A,Summary_CDP,Costs!$B:$B,$H16)/1000 -> 5505.9835 | Y16: =SUMIFS(Costs!R:R,Costs!$A:$A,Summary_CDP,Costs!$B:$B,$H16)/1000 -> 5773.249 | Z16: =SUMIFS(Costs!S:S,Costs!$A:$A,Summary_CDP,Costs!$B:$B,$H16)/1000 -> 5783.7613 | AA16: =SUMIFS(Costs!T:T,Costs!$A:$A,Summary_CDP,Costs!$B:$B,$H16)/1000 -> 6087.1611 | AB16: =SUMIFS(Costs!U:U,Costs!$A:$A,Summary_CDP,Costs!$B:$B,$H16)/1000 -> 7148.4207 | AC16: =SUMIFS(Costs!V:V,Costs!$A:$A,Summary_CDP,Costs!$B:$B,$H16)/1000 -> 8011.8017 | AD16: =SUMIFS(Costs!W:W,Costs!$A:$A,Summary_CDP,Costs!$B:$B,$H16)/1000 -> 8950.4734 | AE16: =SUMIFS(Costs!X:X,Costs!$A:$A,Summary_CDP,Costs!$B:$B,$H16)/1000 -> 9563.7575 | AF16: =SUMIFS(Costs!Y:Y,Costs!$A:$A,Summary_CDP,Costs!$B:$B,$H16)/1000 -> 10675.594 | AG16: =SUMIFS(Costs!Z:Z,Costs!$A:$A,Summary_CDP,Costs!$B:$B,$H16)/1000 -> 10982.834 | AH16: =SUMIFS(Costs!AA:AA,Costs!$A:$A,Summary_CDP,Costs!$B:$B,$H16)/1000 -> 11370.834 | AI16: =SUMIFS(Costs!AB:AB,Costs!$A:$A,Summary_CDP,Costs!$B:$B,$H16)/1000 -> 12440.226 | AJ16: =SUMIFS(Costs!AC:AC,Costs!$A:$A,Summary_CDP,Costs!$B:$B,$H16)/1000 -> 15027.623 | AK16: =SUMIFS(Costs!AD:AD,Costs!$A:$A,Summary_CDP,Costs!$B:$B,$H16)/1000 -> 14916.946
H17: Fuel | I17: =NPV(WACC,J17:AK17)/(1+WACC)^2 -> 10360.023 | J17: =SUMIFS(Costs!C:C,Costs!$A:$A,Summary_CDP,Costs!$B:$B,$H17)/1000 -> 2571.4853 | K17: =SUMIFS(Costs!D:D,Costs!$A:$A,Summary_CDP,Costs!$B:$B,$H17)/1000 -> 1956.8224 | L17: =SUMIFS(Costs!E:E,Costs!$A:$A,Summary_CDP,Costs!$B:$B,$H17)/1000 -> 1452.8799 | M17: =SUMIFS(Costs!F:F,Costs!$A:$A,Summary_CDP,Costs!$B:$B,$H17)/1000 -> 1372.4358 | N17: =SUMIFS(Costs!G:G,Costs!$A:$A,Summary_CDP,Costs!$B:$B,$H17)/1000 -> 1400.8115 | O17: =SUMIFS(Costs!H:H,Costs!$A:$A,Summary_CDP,Costs!$B:$B,$H17)/1000 -> 1343.8659 | P17: =SUMIFS(Costs!I:I,Costs!$A:$A,Summary_CDP,Costs!$B:$B,$H17)/1000 -> 1010.4777 | Q17: =SUMIFS(Costs!J:J,Costs!$A:$A,Summary_CDP,Costs!$B:$B,$H17)/1000 -> 644.95658 | R17: =SUMIFS(Costs!K:K,Costs!$A:$A,Summary_CDP,Costs!$B:$B,$H17)/1000 -> 543.91285 | S17: =SUMIFS(Costs!L:L,Costs!$A:$A,Summary_CDP,Costs!$B:$B,$H17)/1000 -> 382.17329 | T17: =SUMIFS(Costs!M:M,Costs!$A:$A,Summary_CDP,Costs!$B:$B,$H17)/1000 -> 365.33457 | U17: =SUMIFS(Costs!N:N,Costs!$A:$A,Summary_CDP,Costs!$B:$B,$H17)/1000 -> 634.76277 | V17: =SUMIFS(Costs!O:O,Costs!$A:$A,Summary_CDP,Costs!$B:$B,$H17)/1000 -> 421.46356 | W17: =SUMIFS(Costs!P:P,Costs!$A:$A,Summary_CDP,Costs!$B:$B,$H17)/1000 -> 351.92054 | X17: =SUMIFS(Costs!Q:Q,Costs!$A:$A,Summary_CDP,Costs!$B:$B,$H17)/1000 -> 323.47891 | Y17: =SUMIFS(Costs!R:R,Costs!$A:$A,Summary_CDP,Costs!$B:$B,$H17)/1000 -> 1002.8373 | Z17: =SUMIFS(Costs!S:S,Costs!$A:$A,Summary_CDP,Costs!$B:$B,$H17)/1000 -> 361.3878 | AA17: =SUMIFS(Costs!T:T,Costs!$A:$A,Summary_CDP,Costs!$B:$B,$H17)/1000 -> 356.94145 | AB17: =SUMIFS(Costs!U:U,Costs!$A:$A,Summary_CDP,Costs!$B:$B,$H17)/1000 -> 655.51779 | AC17: =SUMIFS(Costs!V:V,Costs!$A:$A,Summary_CDP,Costs!$B:$B,$H17)/1000 -> 573.3398 | AD17: =SUMIFS(Costs!W:W,Costs!$A:$A,Summary_CDP,Costs!$B:$B,$H17)/1000 -> 973.89924 | AE17: =SUMIFS(Costs!X:X,Costs!$A:$A,Summary_CDP,Costs!$B:$B,$H17)/1000 -> 371.55054 | AF17: =SUMIFS(Costs!Y:Y,Costs!$A:$A,Summary_CDP,Costs!$B:$B,$H17)/1000 -> 560.37162 | AG17: =SUMIFS(Costs!Z:Z,Costs!$A:$A,Summary_CDP,Costs!$B:$B,$H17)/1000 -> 179.03776 | AH17: =SUMIFS(Costs!AA:AA,Costs!$A:$A,Summary_CDP,Costs!$B:$B,$H17)/1000 -> 402.01826 | AI17: =SUMIFS(Costs!AB:AB,Costs!$A:$A,Summary_CDP,Costs!$B:$B,$H17)/1000 -> 220.80547 | AJ17: =SUMIFS(Costs!AC:AC,Costs!$A:$A,Summary_CDP,Costs!$B:$B,$H17)/1000 -> 1428.3273 | AK17: =SUMIFS(Costs!AD:AD,Costs!$A:$A,Summary_CDP,Costs!$B:$B,$H17)/1000 -> 168.70515
H18: VOM | I18: =NPV(WACC,J18:AK18)/(1+WACC)^2 -> 2758.2126 | J18: =SUMIFS(Costs!C:C,Costs!$A:$A,Summary_CDP,Costs!$B:$B,$H18)/1000 -> 667.55342 | K18: =SUMIFS(Costs!D:D,Costs!$A:$A,Summary_CDP,Costs!$B:$B,$H18)/1000 -> 554.62779 | L18: =SUMIFS(Costs!E:E,Costs!$A:$A,Summary_CDP,Costs!$B:$B,$H18)/1000 -> 432.85201 | M18: =SUMIFS(Costs!F:F,Costs!$A:$A,Summary_CDP,Costs!$B:$B,$H18)/1000 -> 397.51649 | N18: =SUMIFS(Costs!G:G,Costs!$A:$A,Summary_CDP,Costs!$B:$B,$H18)/1000 -> 355.12307 | O18: =SUMIFS(Costs!H:H,Costs!$A:$A,Summary_CDP,Costs!$B:$B,$H18)/1000 -> 301.91409 | P18: =SUMIFS(Costs!I:I,Costs!$A:$A,Summary_CDP,Costs!$B:$B,$H18)/1000 -> 245.75677 | Q18: =SUMIFS(Costs!J:J,Costs!$A:$A,Summary_CDP,Costs!$B:$B,$H18)/1000 -> 183.92175 | R18: =SUMIFS(Costs!K:K,Costs!$A:$A,Summary_CDP,Costs!$B:$B,$H18)/1000 -> 136.31456 | S18: =SUMIFS(Costs!L:L,Costs!$A:$A,Summary_CDP,Costs!$B:$B,$H18)/1000 -> 151.58821 | T18: =SUMIFS(Costs!M:M,Costs!$A:$A,Summary_CDP,Costs!$B:$B,$H18)/1000 -> 146.8435 | U18: =SUMIFS(Costs!N:N,Costs!$A:$A,Summary_CDP,Costs!$B:$B,$H18)/1000 -> 157.39793 | V18: =SUMIFS(Costs!O:O,Costs!$A:$A,Summary_CDP,Costs!$B:$B,$H18)/1000 -> 145.72582 | W18: =SUMIFS(Costs!P:P,Costs!$A:$A,Summary_CDP,Costs!$B:$B,$H18)/1000 -> 124.43534 | X18: =SUMIFS(Costs!Q:Q,Costs!$A:$A,Summary_CDP,Costs!$B:$B,$H18)/1000 -> 137.79777 | Y18: =SUMIFS(Costs!R:R,Costs!$A:$A,Summary_CDP,Costs!$B:$B,$H18)/1000 -> 180.31557 | Z18: =SUMIFS(Costs!S:S,Costs!$A:$A,Summary_CDP,Costs!$B:$B,$H18)/1000 -> 86.469488 | AA18: =SUMIFS(Costs!T:T,Costs!$A:$A,Summary_CDP,Costs!$B:$B,$H18)/1000 -> 126.78679 | AB18: =SUMIFS(Costs!U:U,Costs!$A:$A,Summary_CDP,Costs!$B:$B,$H18)/1000 -> 141.47629 | AC18: =SUMIFS(Costs!V:V,Costs!$A:$A,Summary_CDP,Costs!$B:$B,$H18)/1000 -> 111.32145 | AD18: =SUMIFS(Costs!W:W,Costs!$A:$A,Summary_CDP,Costs!$B:$B,$H18)/1000 -> 133.43982 | AE18: =SUMIFS(Costs!X:X,Costs!$A:$A,Summary_CDP,Costs!$B:$B,$H18)/1000 -> 114.55579 | AF18: =SUMIFS(Costs!Y:Y,Costs!$A:$A,Summary_CDP,Costs!$B:$B,$H18)/1000 -> 95.392635 | AG18: =SUMIFS(Costs!Z:Z,Costs!$A:$A,Summary_CDP,Costs!$B:$B,$H18)/1000 -> 86.956633 | AH18: =SUMIFS(Costs!AA:AA,Costs!$A:$A,Summary_CDP,Costs!$B:$B,$H18)/1000 -> 95.554274 | AI18: =SUMIFS(Costs!AB:AB,Costs!$A:$A,Summary_CDP,Costs!$B:$B,$H18)/1000 -> 96.589679 | AJ18: =SUMIFS(Costs!AC:AC,Costs!$A:$A,Summary_CDP,Costs!$B:$B,$H18)/1000 -> 128.91477 | AK18: =SUMIFS(Costs!AD:AD,Costs!$A:$A,Summary_CDP,Costs!$B:$B,$H18)/1000 -> 55.764594
H19: DSP+USE | I19: =NPV(WACC,J19:AK19)/(1+WACC)^2 -> 1694.1682 | J19: =SUMIFS(Costs!C:C,Costs!$A:$A,Summary_CDP,Costs!$B:$B,$H19)/1000 -> 0 | K19: =SUMIFS(Costs!D:D,Costs!$A:$A,Summary_CDP,Costs!$B:$B,$H19)/1000 -> 0 | L19: =SUMIFS(Costs!E:E,Costs!$A:$A,Summary_CDP,Costs!$B:$B,$H19)/1000 -> 0.0076741499 | M19: =SUMIFS(Costs!F:F,Costs!$A:$A,Summary_CDP,Costs!$B:$B,$H19)/1000 -> 23.864212 | N19: =SUMIFS(Costs!G:G,Costs!$A:$A,Summary_CDP,Costs!$B:$B,$H19)/1000 -> 1.9656235 | O19: =SUMIFS(Costs!H:H,Costs!$A:$A,Summary_CDP,Costs!$B:$B,$H19)/1000 -> 6.3085562 | P19: =SUMIFS(Costs!I:I,Costs!$A:$A,Summary_CDP,Costs!$B:$B,$H19)/1000 -> 0 | Q19: =SUMIFS(Costs!J:J,Costs!$A:$A,Summary_CDP,Costs!$B:$B,$H19)/1000 -> 46.927084 | R19: =SUMIFS(Costs!K:K,Costs!$A:$A,Summary_CDP,Costs!$B:$B,$H19)/1000 -> 28.75505 | S19: =SUMIFS(Costs!L:L,Costs!$A:$A,Summary_CDP,Costs!$B:$B,$H19)/1000 -> 40.079009 | T19: =SUMIFS(Costs!M:M,Costs!$A:$A,Summary_CDP,Costs!$B:$B,$H19)/1000 -> 5.3567201 | U19: =SUMIFS(Costs!N:N,Costs!$A:$A,Summary_CDP,Costs!$B:$B,$H19)/1000 -> 144.84237 | V19: =SUMIFS(Costs!O:O,Costs!$A:$A,Summary_CDP,Costs!$B:$B,$H19)/1000 -> 96.210597 | W19: =SUMIFS(Costs!P:P,Costs!$A:$A,Summary_CDP,Costs!$B:$B,$H19)/1000 -> 165.30943 | X19: =SUMIFS(Costs!Q:Q,Costs!$A:$A,Summary_CDP,Costs!$B:$B,$H19)/1000 -> 125.91588 | Y19: =SUMIFS(Costs!R:R,Costs!$A:$A,Summary_CDP,Costs!$B:$B,$H19)/1000 -> 554.11704 | Z19: =SUMIFS(Costs!S:S,Costs!$A:$A,Summary_CDP,Costs!$B:$B,$H19)/1000 -> 261.1371 | AA19: =SUMIFS(Costs!T:T,Costs!$A:$A,Summary_CDP,Costs!$B:$B,$H19)/1000 -> 506.7974 | AB19: =SUMIFS(Costs!U:U,Costs!$A:$A,Summary_CDP,Costs!$B:$B,$H19)/1000 -> 602.5884 | AC19: =SUMIFS(Costs!V:V,Costs!$A:$A,Summary_CDP,Costs!$B:$B,$H19)/1000 -> 599.63019 | AD19: =SUMIFS(Costs!W:W,Costs!$A:$A,Summary_CDP,Costs!$B:$B,$H19)/1000 -> 665.73169 | AE19: =SUMIFS(Costs!X:X,Costs!$A:$A,Summary_CDP,Costs!$B:$B,$H19)/1000 -> 714.838 | AF19: =SUMIFS(Costs!Y:Y,Costs!$A:$A,Summary_CDP,Costs!$B:$B,$H19)/1000 -> 709.05928 | AG19: =SUMIFS(Costs!Z:Z,Costs!$A:$A,Summary_CDP,Costs!$B:$B,$H19)/1000 -> 958.97789 | AH19: =SUMIFS(Costs!AA:AA,Costs!$A:$A,Summary_CDP,Costs!$B:$B,$H19)/1000 -> 491.4111 | AI19: =SUMIFS(Costs!AB:AB,Costs!$A:$A,Summary_CDP,Costs!$B:$B,$H19)/1000 -> 733.17212 | AJ19: =SUMIFS(Costs!AC:AC,Costs!$A:$A,Summary_CDP,Costs!$B:$B,$H19)/1000 -> 1095.43 | AK19: =SUMIFS(Costs!AD:AD,Costs!$A:$A,Summary_CDP,Costs!$B:$B,$H19)/1000 -> 344.92388
H20: REZ Augmentation | I20: =NPV(WACC,J20:AK20)/(1+WACC)^2 -> 15405.894 | J20: =SUMIFS(Costs!C:C,Costs!$A:$A,Summary_CDP,Costs!$B:$B,$H20)/1000 -> 0 | K20: =SUMIFS(Costs!D:D,Costs!$A:$A,Summary_CDP,Costs!$B:$B,$H20)/1000 -> 0 | L20: =SUMIFS(Costs!E:E,Costs!$A:$A,Summary_CDP,Costs!$B:$B,$H20)/1000 -> 62.964973 | M20: =SUMIFS(Costs!F:F,Costs!$A:$A,Summary_CDP,Costs!$B:$B,$H20)/1000 -> 149.27509 | N20: =SUMIFS(Costs!G:G,Costs!$A:$A,Summary_CDP,Costs!$B:$B,$H20)/1000 -> 297.57121 | O20: =SUMIFS(Costs!H:H,Costs!$A:$A,Summary_CDP,Costs!$B:$B,$H20)/1000 -> 451.72413 | P20: =SUMIFS(Costs!I:I,Costs!$A:$A,Summary_CDP,Costs!$B:$B,$H20)/1000 -> 602.43932 | Q20: =SUMIFS(Costs!J:J,Costs!$A:$A,Summary_CDP,Costs!$B:$B,$H20)/1000 -> 722.14499 | R20: =SUMIFS(Costs!K:K,Costs!$A:$A,Summary_CDP,Costs!$B:$B,$H20)/1000 -> 877.81765 | S20: =SUMIFS(Costs!L:L,Costs!$A:$A,Summary_CDP,Costs!$B:$B,$H20)/1000 -> 897.42637 | T20: =SUMIFS(Costs!M:M,Costs!$A:$A,Summary_CDP,Costs!$B:$B,$H20)/1000 -> 1115.0498 | U20: =SUMIFS(Costs!N:N,Costs!$A:$A,Summary_CDP,Costs!$B:$B,$H20)/1000 -> 1743.3625 | V20: =SUMIFS(Costs!O:O,Costs!$A:$A,Summary_CDP,Costs!$B:$B,$H20)/1000 -> 2098.411 | W20: =SUMIFS(Costs!P:P,Costs!$A:$A,Summary_CDP,Costs!$B:$B,$H20)/1000 -> 2309.0609 | X20: =SUMIFS(Costs!Q:Q,Costs!$A:$A,Summary_CDP,Costs!$B:$B,$H20)/1000 -> 2501.4262 | Y20: =SUMIFS(Costs!R:R,Costs!$A:$A,Summary_CDP,Costs!$B:$B,$H20)/1000 -> 2661.7861 | Z20: =SUMIFS(Costs!S:S,Costs!$A:$A,Summary_CDP,Costs!$B:$B,$H20)/1000 -> 2669.0787 | AA20: =SUMIFS(Costs!T:T,Costs!$A:$A,Summary_CDP,Costs!$B:$B,$H20)/1000 -> 2864.1008 | AB20: =SUMIFS(Costs!U:U,Costs!$A:$A,Summary_CDP,Costs!$B:$B,$H20)/1000 -> 3254.3606 | AC20: =SUMIFS(Costs!V:V,Costs!$A:$A,Summary_CDP,Costs!$B:$B,$H20)/1000 -> 3783.8368 | AD20: =SUMIFS(Costs!W:W,Costs!$A:$A,Summary_CDP,Costs!$B:$B,$H20)/1000 -> 3974.4237 | AE20: =SUMIFS(Costs!X:X,Costs!$A:$A,Summary_CDP,Costs!$B:$B,$H20)/1000 -> 4489.4307 | AF20: =SUMIFS(Costs!Y:Y,Costs!$A:$A,Summary_CDP,Costs!$B:$B,$H20)/1000 -> 5217.6553 | AG20: =SUMIFS(Costs!Z:Z,Costs!$A:$A,Summary_CDP,Costs!$B:$B,$H20)/1000 -> 5414.7676 | AH20: =SUMIFS(Costs!AA:AA,Costs!$A:$A,Summary_CDP,Costs!$B:$B,$H20)/1000 -> 5679.092 | AI20: =SUMIFS(Costs!AB:AB,Costs!$A:$A,Summary_CDP,Costs!$B:$B,$H20)/1000 -> 6140.5514 | AJ20: =SUMIFS(Costs!AC:AC,Costs!$A:$A,Summary_CDP,Costs!$B:$B,$H20)/1000 -> 7420.8291 | AK20: =SUMIFS(Costs!AD:AD,Costs!$A:$A,Summary_CDP,Costs!$B:$B,$H20)/1000 -> 7429.0215
H21: Flow Path Augmentation | I21: =NPV(WACC,J21:AK21)/(1+WACC)^2 -> 8844.3062 | J21: =SUMIFS(Costs!C:C,Costs!$A:$A,Summary_CDP,Costs!$B:$B,$H21)/1000 -> 0 | K21: =SUMIFS(Costs!D:D,Costs!$A:$A,Summary_CDP,Costs!$B:$B,$H21)/1000 -> 0 | L21: =SUMIFS(Costs!E:E,Costs!$A:$A,Summary_CDP,Costs!$B:$B,$H21)/1000 -> 0 | M21: =SUMIFS(Costs!F:F,Costs!$A:$A,Summary_CDP,Costs!$B:$B,$H21)/1000 -> 0 | N21: =SUMIFS(Costs!G:G,Costs!$A:$A,Summary_CDP,Costs!$B:$B,$H21)/1000 -> 242.49666 | O21: =SUMIFS(Costs!H:H,Costs!$A:$A,Summary_CDP,Costs!$B:$B,$H21)/1000 -> 535.93068 | P21: =SUMIFS(Costs!I:I,Costs!$A:$A,Summary_CDP,Costs!$B:$B,$H21)/1000 -> 826.2301 | Q21: =SUMIFS(Costs!J:J,Costs!$A:$A,Summary_CDP,Costs!$B:$B,$H21)/1000 -> 936.63792 | R21: =SUMIFS(Costs!K:K,Costs!$A:$A,Summary_CDP,Costs!$B:$B,$H21)/1000 -> 1149.7041 | S21: =SUMIFS(Costs!L:L,Costs!$A:$A,Summary_CDP,Costs!$B:$B,$H21)/1000 -> 1405.8711 | T21: =SUMIFS(Costs!M:M,Costs!$A:$A,Summary_CDP,Costs!$B:$B,$H21)/1000 -> 1405.8711 | U21: =SUMIFS(Costs!N:N,Costs!$A:$A,Summary_CDP,Costs!$B:$B,$H21)/1000 -> 1405.8711 | V21: =SUMIFS(Costs!O:O,Costs!$A:$A,Summary_CDP,Costs!$B:$B,$H21)/1000 -> 1405.8711 | W21: =SUMIFS(Costs!P:P,Costs!$A:$A,Summary_CDP,Costs!$B:$B,$H21)/1000 -> 1405.8711 | X21: =SUMIFS(Costs!Q:Q,Costs!$A:$A,Summary_CDP,Costs!$B:$B,$H21)/1000 -> 1405.8711 | Y21: =SUMIFS(Costs!R:R,Costs!$A:$A,Summary_CDP,Costs!$B:$B,$H21)/1000 -> 1405.8711 | Z21: =SUMIFS(Costs!S:S,Costs!$A:$A,Summary_CDP,Costs!$B:$B,$H21)/1000 -> 1405.8711 | AA21: =SUMIFS(Costs!T:T,Costs!$A:$A,Summary_CDP,Costs!$B:$B,$H21)/1000 -> 1541.0075 | AB21: =SUMIFS(Costs!U:U,Costs!$A:$A,Summary_CDP,Costs!$B:$B,$H21)/1000 -> 1541.0075 | AC21: =SUMIFS(Costs!V:V,Costs!$A:$A,Summary_CDP,Costs!$B:$B,$H21)/1000 -> 1724.9044 | AD21: =SUMIFS(Costs!W:W,Costs!$A:$A,Summary_CDP,Costs!$B:$B,$H21)/1000 -> 1724.9044 | AE21: =SUMIFS(Costs!X:X,Costs!$A:$A,Summary_CDP,Costs!$B:$B,$H21)/1000 -> 1724.9044 | AF21: =SUMIFS(Costs!Y:Y,Costs!$A:$A,Summary_CDP,Costs!$B:$B,$H21)/1000 -> 1926.6512 | AG21: =SUMIFS(Costs!Z:Z,Costs!$A:$A,Summary_CDP,Costs!$B:$B,$H21)/1000 -> 1926.6512 | AH21: =SUMIFS(Costs!AA:AA,Costs!$A:$A,Summary_CDP,Costs!$B:$B,$H21)/1000 -> 1926.6512 | AI21: =SUMIFS(Costs!AB:AB,Costs!$A:$A,Summary_CDP,Costs!$B:$B,$H21)/1000 -> 1926.6512 | AJ21: =SUMIFS(Costs!AC:AC,Costs!$A:$A,Summary_CDP,Costs!$B:$B,$H21)/1000 -> 1926.6512 | AK21: =SUMIFS(Costs!AD:AD,Costs!$A:$A,Summary_CDP,Costs!$B:$B,$H21)/1000 -> 1926.6512
H22: NPV and annual costs | I22: =SUM(I15:I21) -> 279338.25 | J22: =SUM(J15:J21) -> 7169.3478 | K22: =SUM(K15:K21) -> 7936.7185 | L22: =SUM(L15:L21) -> 10246.393 | M22: =SUM(M15:M21) -> 11003.592 | N22: =SUM(N15:N21) -> 14035.81 | O22: =SUM(O15:O21) -> 15758.017 | P22: =SUM(P15:P21) -> 16480.207 | ... AK22: =SUM(AK15:AK21) -> 99631.903
H23: *Net present value as at 1 July 2021
A29: =B30&" capacity by year" -> NEM capacity by year
A30: Select region | B30: NEM
H32: Capacity (MW) | I32: 2023-24 | J32: 2024-25 | K32: 2025-26 | L32: 2026-27 | M32: 2027-28 | N32: 2028-29 | O32: 2029-30 | P32: 2030-31 | Q32: 2031-32 | R32: 2032-33 | S32: 2033-34 | T32: 2034-35 | U32: 2035-36 | V32: 2036-37 | W32: 2037-38 | X32: 2038-39 | Y32: 2039-40 | Z32: 2040-41 | AA32: 2041-42 | AB32: 2042-43 | AC32: 2043-44 | AD32: 2044-45 | AE32: 2045-46 | AF32: 2046-47 | AG32: 2047-48 | AH32: 2048-49 | AI32: 2049-50 | AJ32: 2050-51
H33: Black Coal | I33: =SUMIFS(Capacity!E:E,Capacity!$A:$A,Summary_CDP,Capacity!$B:$B,IF($B$30="NEM","*",$B$30),Capacity!$C:$C,$H33) -> 16456 | J33: =SUMIFS(Capacity!F:F,Capacity!$A:$A,Summary_CDP,Capacity!$B:$B,IF($B$30="NEM","*",$B$30),Capacity!$C:$C,$H33) -> 16456 | K33: =SUMIFS(Capacity!G:G,Capacity!$A:$A,Summary_CDP,Capacity!$B:$B,IF($B$30="NEM","*",$B$30),Capacity!$C:$C,$H33) -> 10402 | L33: =SUMIFS(Capacity!H:H,Capacity!$A:$A,Summary_CDP,Capacity!$B:$B,IF($B$30="NEM","*",$B$30),Capacity!$C:$C,$H33) -> 7547 | M33: =SUMIFS(Capacity!I:I,Capacity!$A:$A,Summary_CDP,Capacity!$B:$B,IF($B$30="NEM","*",$B$30),Capacity!$C:$C,$H33) -> 4202 | N33: =SUMIFS(Capacity!J:J,Capacity!$A:$A,Summary_CDP,Capacity!$B:$B,IF($B$30="NEM","*",$B$30),Capacity!$C:$C,$H33) -> 3082 | O33: =SUMIFS(Capacity!K:K,Capacity!$A:$A,Summary_CDP,Capacity!$B:$B,IF($B$30="NEM","*",$B$30),Capacity!$C:$C,$H33) -> 2242 | P33: =SUMIFS(Capacity!L:L,Capacity!$A:$A,Summary_CDP,Capacity!$B:$B,IF($B$30="NEM","*",$B$30),Capacity!$C:$C,$H33) -> 0 | Q33: =SUMIFS(Capacity!M:M,Capacity!$A:$A,Summary_CDP,Capacity!$B:$B,IF($B$30="NEM","*",$B$30),Capacity!$C:$C,$H33) -> 0 | R33: =SUMIFS(Capacity!N:N,Capacity!$A:$A,Summary_CDP,Capacity!$B:$B,IF($B$30="NEM","*",$B$30),Capacity!$C:$C,$H33) -> 0 | S33: =SUMIFS(Capacity!O:O,Capacity!$A:$A,Summary_CDP,Capacity!$B:$B,IF($B$30="NEM","*",$B$30),Capacity!$C:$C,$H33) -> 0 | T33: =SUMIFS(Capacity!P:P,Capacity!$A:$A,Summary_CDP,Capacity!$B:$B,IF($B$30="NEM","*",$B$30),Capacity!$C:$C,$H33) -> 0 | U33: =SUMIFS(Capacity!Q:Q,Capacity!$A:$A,Summary_CDP,Capacity!$B:$B,IF($B$30="NEM","*",$B$30),Capacity!$C:$C,$H33) -> 0 | V33: =SUMIFS(Capacity!R:R,Capacity!$A:$A,Summary_CDP,Capacity!$B:$B,IF($B$30="NEM","*",$B$30),Capacity!$C:$C,$H33) -> 0 | W33: =SUMIFS(Capacity!S:S,Capacity!$A:$A,Summary_CDP,Capacity!$B:$B,IF($B$30="NEM","*",$B$30),Capacity!$C:$C,$H33) -> 0 | X33: =SUMIFS(Capacity!T:T,Capacity!$A:$A,Summary_CDP,Capacity!$B:$B,IF($B$30="NEM","*",$B$30),Capacity!$C:$C,$H33) -> 0 | Y33: =SUMIFS(Capacity!U:U,Capacity!$A:$A,Summary_CDP,Capacity!$B:$B,IF($B$30="NEM","*",$B$30),Capacity!$C:$C,$H33) -> 0 | Z33: =SUMIFS(Capacity!V:V,Capacity!$A:$A,Summary_CDP,Capacity!$B:$B,IF($B$30="NEM","*",$B$30),Capacity!$C:$C,$H33) -> 0 | AA33: =SUMIFS(Capacity!W:W,Capacity!$A:$A,Summary_CDP,Capacity!$B:$B,IF($B$30="NEM","*",$B$30),Capacity!$C:$C,$H33) -> 0 | AB33: =SUMIFS(Capacity!X:X,Capacity!$A:$A,Summary_CDP,Capacity!$B:$B,IF($B$30="NEM","*",$B$30),Capacity!$C:$C,$H33) -> 0 | AC33: =SUMIFS(Capacity!Y:Y,Capacity!$A:$A,Summary_CDP,Capacity!$B:$B,IF($B$30="NEM","*",$B$30),Capacity!$C:$C,$H33) -> 0 | AD33: =SUMIFS(Capacity!Z:Z,Capacity!$A:$A,Summary_CDP,Capacity!$B:$B,IF($B$30="NEM","*",$B$30),Capacity!$C:$C,$H33) -> 0 | AE33: =SUMIFS(Capacity!AA:AA,Capacity!$A:$A,Summary_CDP,Capacity!$B:$B,IF($B$30="NEM","*",$B$30),Capacity!$C:$C,$H33) -> 0 | AF33: =SUMIFS(Capacity!AB:AB,Capacity!$A:$A,Summary_CDP,Capacity!$B:$B,IF($B$30="NEM","*",$B$30),Capacity!$C:$C,$H33) -> 0 | AG33: =SUMIFS(Capacity!AC:AC,Capacity!$A:$A,Summary_CDP,Capacity!$B:$B,IF($B$30="NEM","*",$B$30),Capacity!$C:$C,$H33) -> 0 | AH33: =SUMIFS(Capacity!AD:AD,Capacity!$A:$A,Summary_CDP,Capacity!$B:$B,IF($B$30="NEM","*",$B$30),Capacity!$C:$C,$H33) -> 0 | AI33: =SUMIFS(Capacity!AE:AE,Capacity!$A:$A,Summary_CDP,Capacity!$B:$B,IF($B$30="NEM","*",$B$30),Capacity!$C:$C,$H33) -> 0 | AJ33: =SUMIFS(Capacity!AF:AF,Capacity!$A:$A,Summary_CDP,Capacity!$B:$B,IF($B$30="NEM","*",$B$30),Capacity!$C:$C,$H33) -> 0
H34: Brown Coal | I34: =SUMIFS(Capacity!E:E,Capacity!$A:$A,Summary_CDP,Capacity!$B:$B,IF($B$30="NEM","*",$B$30),Capacity!$C:$C,$H34) -> 4820 | J34: =SUMIFS(Capacity!F:F,Capacity!$A:$A,Summary_CDP,Capacity!$B:$B,IF($B$30="NEM","*",$B$30),Capacity!$C:$C,$H34) -> 4820 | K34: =SUMIFS(Capacity!G:G,Capacity!$A:$A,Summary_CDP,Capacity!$B:$B,IF($B$30="NEM","*",$B$30),Capacity!$C:$C,$H34) -> 3385 | L34: =SUMIFS(Capacity!H:H,Capacity!$A:$A,Summary_CDP,Capacity!$B:$B,IF($B$30="NEM","*",$B$30),Capacity!$C:$C,$H34) -> 2805 | M34: =SUMIFS(Capacity!I:I,Capacity!$A:$A,Summary_CDP,Capacity!$B:$B,IF($B$30="NEM","*",$B$30),Capacity!$C:$C,$H34) -> 1665 | N34: =SUMIFS(Capacity!J:J,Capacity!$A:$A,Summary_CDP,Capacity!$B:$B,IF($B$30="NEM","*",$B$30),Capacity!$C:$C,$H34) -> 1120 | O34: =SUMIFS(Capacity!K:K,Capacity!$A:$A,Summary_CDP,Capacity!$B:$B,IF($B$30="NEM","*",$B$30),Capacity!$C:$C,$H34) -> 1120 | P34: =SUMIFS(Capacity!L:L,Capacity!$A:$A,Summary_CDP,Capacity!$B:$B,IF($B$30="NEM","*",$B$30),Capacity!$C:$C,$H34) -> 0 | Q34: =SUMIFS(Capacity!M:M,Capacity!$A:$A,Summary_CDP,Capacity!$B:$B,IF($B$30="NEM","*",$B$30),Capacity!$C:$C,$H34) -> 0 | R34: =SUMIFS(Capacity!N:N,Capacity!$A:$A,Summary_CDP,Capacity!$B:$B,IF($B$30="NEM","*",$B$30),Capacity!$C:$C,$H34) -> 0 | S34: =SUMIFS(Capacity!O:O,Capacity!$A:$A,Summary_CDP,Capacity!$B:$B,IF($B$30="NEM","*",$B$30),Capacity!$C:$C,$H34) -> 0 | T34: =SUMIFS(Capacity!P:P,Capacity!$A:$A,Summary_CDP,Capacity!$B:$B,IF($B$30="NEM","*",$B$30),Capacity!$C:$C,$H34) -> 0 | U34: =SUMIFS(Capacity!Q:Q,Capacity!$A:$A,Summary_CDP,Capacity!$B:$B,IF($B$30="NEM","*",$B$30),Capacity!$C:$C,$H34) -> 0 | V34: =SUMIFS(Capacity!R:R,Capacity!$A:$A,Summary_CDP,Capacity!$B:$B,IF($B$30="NEM","*",$B$30),Capacity!$C:$C,$H34) -> 0 | W34: =SUMIFS(Capacity!S:S,Capacity!$A:$A,Summary_CDP,Capacity!$B:$B,IF($B$30="NEM","*",$B$30),Capacity!$C:$C,$H34) -> 0 | X34: =SUMIFS(Capacity!T:T,Capacity!$A:$A,Summary_CDP,Capacity!$B:$B,IF($B$30="NEM","*",$B$30),Capacity!$C:$C,$H34) -> 0 | Y34: =SUMIFS(Capacity!U:U,Capacity!$A:$A,Summary_CDP,Capacity!$B:$B,IF($B$30="NEM","*",$B$30),Capacity!$C:$C,$H34) -> 0 | Z34: =SUMIFS(Capacity!V:V,Capacity!$A:$A,Summary_CDP,Capacity!$B:$B,IF($B$30="NEM","*",$B$30),Capacity!$C:$C,$H34) -> 0 | AA34: =SUMIFS(Capacity!W:W,Capacity!$A:$A,Summary_CDP,Capacity!$B:$B,IF($B$30="NEM","*",$B$30),Capacity!$C:$C,$H34) -> 0 | AB34: =SUMIFS(Capacity!X:X,Capacity!$A:$A,Summary_CDP,Capacity!$B:$B,IF($B$30="NEM","*",$B$30),Capacity!$C:$C,$H34) -> 0 | AC34: =SUMIFS(Capacity!Y:Y,Capacity!$A:$A,Summary_CDP,Capacity!$B:$B,IF($B$30="NEM","*",$B$30),Capacity!$C:$C,$H34) -> 0 | AD34: =SUMIFS(Capacity!Z:Z,Capacity!$A:$A,Summary_CDP,Capacity!$B:$B,IF($B$30="NEM","*",$B$30),Capacity!$C:$C,$H34) -> 0 | AE34: =SUMIFS(Capacity!AA:AA,Capacity!$A:$A,Summary_CDP,Capacity!$B:$B,IF($B$30="NEM","*",$B$30),Capacity!$C:$C,$H34) -> 0 | AF34: =SUMIFS(Capacity!AB:AB,Capacity!$A:$A,Summary_CDP,Capacity!$B:$B,IF($B$30="NEM","*",$B$30),Capacity!$C:$C,$H34) -> 0 | AG34: =SUMIFS(Capacity!AC:AC,Capacity!$A:$A,Summary_CDP,Capacity!$B:$B,IF($B$30="NEM","*",$B$30),Capacity!$C:$C,$H34) -> 0 | AH34: =SUMIFS(Capacity!AD:AD,Capacity!$A:$A,Summary_CDP,Capacity!$B:$B,IF($B$30="NEM","*",$B$30),Capacity!$C:$C,$H34) -> 0 | AI34: =SUMIFS(Capacity!AE:AE,Capacity!$A:$A,Summary_CDP,Capacity!$B:$B,IF($B$30="NEM","*",$B$30),Capacity!$C:$C,$H34) -> 0 | AJ34: =SUMIFS(Capacity!AF:AF,Capacity!$A:$A,Summary_CDP,Capacity!$B:$B,IF($B$30="NEM","*",$B$30),Capacity!$C:$C,$H34) -> 0
H35: Mid-merit Gas | I35: =SUMIFS(Capacity!E:E,Capacity!$A:$A,Summary_CDP,Capacity!$B:$B,IF($B$30="NEM","*",$B$30),Capacity!$C:$C,$H35) -> 4074.9 | J35: =SUMIFS(Capacity!F:F,Capacity!$A:$A,Summary_CDP,Capacity!$B:$B,IF($B$30="NEM","*",$B$30),Capacity!$C:$C,$H35) -> 4074.9 | K35: =SUMIFS(Capacity!G:G,Capacity!$A:$A,Summary_CDP,Capacity!$B:$B,IF($B$30="NEM","*",$B$30),Capacity!$C:$C,$H35) -> 2386.9 | L35: =SUMIFS(Capacity!H:H,Capacity!$A:$A,Summary_CDP,Capacity!$B:$B,IF($B$30="NEM","*",$B$30),Capacity!$C:$C,$H35) -> 2386.9 | M35: =SUMIFS(Capacity!I:I,Capacity!$A:$A,Summary_CDP,Capacity!$B:$B,IF($B$30="NEM","*",$B$30),Capacity!$C:$C,$H35) -> 2386.9 | N35: =SUMIFS(Capacity!J:J,Capacity!$A:$A,Summary_CDP,Capacity!$B:$B,IF($B$30="NEM","*",$B$30),Capacity!$C:$C,$H35) -> 2386.9 | O35: =SUMIFS(Capacity!K:K,Capacity!$A:$A,Summary_CDP,Capacity!$B:$B,IF($B$30="NEM","*",$B$30),Capacity!$C:$C,$H35) -> 2386.9 | P35: =SUMIFS(Capacity!L:L,Capacity!$A:$A,Summary_CDP,Capacity!$B:$B,IF($B$30="NEM","*",$B$30),Capacity!$C:$C,$H35) -> 2386.9 | Q35: =SUMIFS(Capacity!M:M,Capacity!$A:$A,Summary_CDP,Capacity!$B:$B,IF($B$30="NEM","*",$B$30),Capacity!$C:$C,$H35) -> 2386.9 | R35: =SUMIFS(Capacity!N:N,Capacity!$A:$A,Summary_CDP,Capacity!$B:$B,IF($B$30="NEM","*",$B$30),Capacity!$C:$C,$H35) -> 2386.9 | S35: =SUMIFS(Capacity!O:O,Capacity!$A:$A,Summary_CDP,Capacity!$B:$B,IF($B$30="NEM","*",$B$30),Capacity!$C:$C,$H35) -> 2386.9 | T35: =SUMIFS(Capacity!P:P,Capacity!$A:$A,Summary_CDP,Capacity!$B:$B,IF($B$30="NEM","*",$B$30),Capacity!$C:$C,$H35) -> 2386.9 | U35: =SUMIFS(Capacity!Q:Q,Capacity!$A:$A,Summary_CDP,Capacity!$B:$B,IF($B$30="NEM","*",$B$30),Capacity!$C:$C,$H35) -> 2386.9 | V35: =SUMIFS(Capacity!R:R,Capacity!$A:$A,Summary_CDP,Capacity!$B:$B,IF($B$30="NEM","*",$B$30),Capacity!$C:$C,$H35) -> 2001.9 | W35: =SUMIFS(Capacity!S:S,Capacity!$A:$A,Summary_CDP,Capacity!$B:$B,IF($B$30="NEM","*",$B$30),Capacity!$C:$C,$H35) -> 1472.9 | X35: =SUMIFS(Capacity!T:T,Capacity!$A:$A,Summary_CDP,Capacity!$B:$B,IF($B$30="NEM","*",$B$30),Capacity!$C:$C,$H35) -> 1472.9 | Y35: =SUMIFS(Capacity!U:U,Capacity!$A:$A,Summary_CDP,Capacity!$B:$B,IF($B$30="NEM","*",$B$30),Capacity!$C:$C,$H35) -> 1328.5 | Z35: =SUMIFS(Capacity!V:V,Capacity!$A:$A,Summary_CDP,Capacity!$B:$B,IF($B$30="NEM","*",$B$30),Capacity!$C:$C,$H35) -> 1328.5 | AA35: =SUMIFS(Capacity!W:W,Capacity!$A:$A,Summary_CDP,Capacity!$B:$B,IF($B$30="NEM","*",$B$30),Capacity!$C:$C,$H35) -> 1328.5 | AB35: =SUMIFS(Capacity!X:X,Capacity!$A:$A,Summary_CDP,Capacity!$B:$B,IF($B$30="NEM","*",$B$30),Capacity!$C:$C,$H35) -> 1328.5 | AC35: =SUMIFS(Capacity!Y:Y,Capacity!$A:$A,Summary_CDP,Capacity!$B:$B,IF($B$30="NEM","*",$B$30),Capacity!$C:$C,$H35) -> 888.5 | AD35: =SUMIFS(Capacity!Z:Z,Capacity!$A:$A,Summary_CDP,Capacity!$B:$B,IF($B$30="NEM","*",$B$30),Capacity!$C:$C,$H35) -> 888.5 | AE35: =SUMIFS(Capacity!AA:AA,Capacity!$A:$A,Summary_CDP,Capacity!$B:$B,IF($B$30="NEM","*",$B$30),Capacity!$C:$C,$H35) -> 244 | AF35: =SUMIFS(Capacity!AB:AB,Capacity!$A:$A,Summary_CDP,Capacity!$B:$B,IF($B$30="NEM","*",$B$30),Capacity!$C:$C,$H35) -> 0 | AG35: =SUMIFS(Capacity!AC:AC,Capacity!$A:$A,Summary_CDP,Capacity!$B:$B,IF($B$30="NEM","*",$B$30),Capacity!$C:$C,$H35) -> 0 | AH35: =SUMIFS(Capacity!AD:AD,Capacity!$A:$A,Summary_CDP,Capacity!$B:$B,IF($B$30="NEM","*",$B$30),Capacity!$C:$C,$H35) -> 0 | AI35: =SUMIFS(Capacity!AE:AE,Capacity!$A:$A,Summary_CDP,Capacity!$B:$B,IF($B$30="NEM","*",$B$30),Capacity!$C:$C,$H35) -> 0 | AJ35: =SUMIFS(Capacity!AF:AF,Capacity!$A:$A,Summary_CDP,Capacity!$B:$B,IF($B$30="NEM","*",$B$30),Capacity!$C:$C,$H35) -> 0
H36: Mid-merit Gas with CCS | I36: =SUMIFS(Capacity!E:E,Capacity!$A:$A,Summary_CDP,Capacity!$B:$B,IF($B$30="NEM","*",$B$30),Capacity!$C:$C,$H36) -> 0 | J36: =SUMIFS(Capacity!F:F,Capacity!$A:$A,Summary_CDP,Capacity!$B:$B,IF($B$30="NEM","*",$B$30),Capacity!$C:$C,$H36) -> 0 | K36: =SUMIFS(Capacity!G:G,Capacity!$A:$A,Summary_CDP,Capacity!$B:$B,IF($B$30="NEM","*",$B$30),Capacity!$C:$C,$H36) -> 0 | L36: =SUMIFS(Capacity!H:H,Capacity!$A:$A,Summary_CDP,Capacity!$B:$B,IF($B$30="NEM","*",$B$30),Capacity!$C:$C,$H36) -> 0 | M36: =SUMIFS(Capacity!I:I,Capacity!$A:$A,Summary_CDP,Capacity!$B:$B,IF($B$30="NEM","*",$B$30),Capacity!$C:$C,$H36) -> 0 | N36: =SUMIFS(Capacity!J:J,Capacity!$A:$A,Summary_CDP,Capacity!$B:$B,IF($B$30="NEM","*",$B$30),Capacity!$C:$C,$H36) -> 0 | O36: =SUMIFS(Capacity!K:K,Capacity!$A:$A,Summary_CDP,Capacity!$B:$B,IF($B$30="NEM","*",$B$30),Capacity!$C:$C,$H36) -> 0 | P36: =SUMIFS(Capacity!L:L,Capacity!$A:$A,Summary_CDP,Capacity!$B:$B,IF($B$30="NEM","*",$B$30),Capacity!$C:$C,$H36) -> 0 | Q36: =SUMIFS(Capacity!M:M,Capacity!$A:$A,Summary_CDP,Capacity!$B:$B,IF($B$30="NEM","*",$B$30),Capacity!$C:$C,$H36) -> 0 | R36: =SUMIFS(Capacity!N:N,Capacity!$A:$A,Summary_CDP,Capacity!$B:$B,IF($B$30="NEM","*",$B$30),Capacity!$C:$C,$H36) -> 0 | S36: =SUMIFS(Capacity!O:O,Capacity!$A:$A,Summary_CDP,Capacity!$B:$B,IF($B$30="NEM","*",$B$30),Capacity!$C:$C,$H36) -> 0 | T36: =SUMIFS(Capacity!P:P,Capacity!$A:$A,Summary_CDP,Capacity!$B:$B,IF($B$30="NEM","*",$B$30),Capacity!$C:$C,$H36) -> 0 | U36: =SUMIFS(Capacity!Q:Q,Capacity!$A:$A,Summary_CDP,Capacity!$B:$B,IF($B$30="NEM","*",$B$30),Capacity!$C:$C,$H36) -> 0 | V36: =SUMIFS(Capacity!R:R,Capacity!$A:$A,Summary_CDP,Capacity!$B:$B,IF($B$30="NEM","*",$B$30),Capacity!$C:$C,$H36) -> 0 | W36: =SUMIFS(Capacity!S:S,Capacity!$A:$A,Summary_CDP,Capacity!$B:$B,IF($B$30="NEM","*",$B$30),Capacity!$C:$C,$H36) -> 0 | X36: =SUMIFS(Capacity!T:T,Capacity!$A:$A,Summary_CDP,Capacity!$B:$B,IF($B$30="NEM","*",$B$30),Capacity!$C:$C,$H36) -> 0 | Y36: =SUMIFS(Capacity!U:U,Capacity!$A:$A,Summary_CDP,Capacity!$B:$B,IF($B$30="NEM","*",$B$30),Capacity!$C:$C,$H36) -> 0 | Z36: =SUMIFS(Capacity!V:V,Capacity!$A:$A,Summary_CDP,Capacity!$B:$B,IF($B$30="NEM","*",$B$30),Capacity!$C:$C,$H36) -> 0 | AA36: =SUMIFS(Capacity!W:W,Capacity!$A:$A,Summary_CDP,Capacity!$B:$B,IF($B$30="NEM","*",$B$30),Capacity!$C:$C,$H36) -> 0 | AB36: =SUMIFS(Capacity!X:X,Capacity!$A:$A,Summary_CDP,Capacity!$B:$B,IF($B$30="NEM","*",$B$30),Capacity!$C:$C,$H36) -> 0 | AC36: =SUMIFS(Capacity!Y:Y,Capacity!$A:$A,Summary_CDP,Capacity!$B:$B,IF($B$30="NEM","*",$B$30),Capacity!$C:$C,$H36) -> 0 | AD36: =SUMIFS(Capacity!Z:Z,Capacity!$A:$A,Summary_CDP,Capacity!$B:$B,IF($B$30="NEM","*",$B$30),Capacity!$C:$C,$H36) -> 0 | AE36: =SUMIFS(Capacity!AA:AA,Capacity!$A:$A,Summary_CDP,Capacity!$B:$B,IF($B$30="NEM","*",$B$30),Capacity!$C:$C,$H36) -> 0 | AF36: =SUMIFS(Capacity!AB:AB,Capacity!$A:$A,Summary_CDP,Capacity!$B:$B,IF($B$30="NEM","*",$B$30),Capacity!$C:$C,$H36) -> 0 | AG36: =SUMIFS(Capacity!AC:AC,Capacity!$A:$A,Summary_CDP,Capacity!$B:$B,IF($B$30="NEM","*",$B$30),Capacity!$C:$C,$H36) -> 0 | AH36: =SUMIFS(Capacity!AD:AD,Capacity!$A:$A,Summary_CDP,Capacity!$B:$B,IF($B$30="NEM","*",$B$30),Capacity!$C:$C,$H36) -> 0 | AI36: =SUMIFS(Capacity!AE:AE,Capacity!$A:$A,Summary_CDP,Capacity!$B:$B,IF($B$30="NEM","*",$B$30),Capacity!$C:$C,$H36) -> 0 | AJ36: =SUMIFS(Capacity!AF:AF,Capacity!$A:$A,Summary_CDP,Capacity!$B:$B,IF($B$30="NEM","*",$B$30),Capacity!$C:$C,$H36) -> 0
H37: Peaking Gas+Liquids | I37: =SUMIFS(Capacity!E:E,Capacity!$A:$A,Summary_CDP,Capacity!$B:$B,IF($B$30="NEM","*",$B$30),Capacity!$C:$C,$H37) -> 8305.359 | J37: =SUMIFS(Capacity!F:F,Capacity!$A:$A,Summary_CDP,Capacity!$B:$B,IF($B$30="NEM","*",$B$30),Capacity!$C:$C,$H37) -> 8305.359 | K37: =SUMIFS(Capacity!G:G,Capacity!$A:$A,Summary_CDP,Capacity!$B:$B,IF($B$30="NEM","*",$B$30),Capacity!$C:$C,$H37) -> 8305.359 | L37: =SUMIFS(Capacity!H:H,Capacity!$A:$A,Summary_CDP,Capacity!$B:$B,IF($B$30="NEM","*",$B$30),Capacity!$C:$C,$H37) -> 8305.359 | M37: =SUMIFS(Capacity!I:I,Capacity!$A:$A,Summary_CDP,Capacity!$B:$B,IF($B$30="NEM","*",$B$30),Capacity!$C:$C,$H37) -> 8305.359 | N37: =SUMIFS(Capacity!J:J,Capacity!$A:$A,Summary_CDP,Capacity!$B:$B,IF($B$30="NEM","*",$B$30),Capacity!$C:$C,$H37) -> 8773.7137 | O37: =SUMIFS(Capacity!K:K,Capacity!$A:$A,Summary_CDP,Capacity!$B:$B,IF($B$30="NEM","*",$B$30),Capacity!$C:$C,$H37) -> 8773.7137 | P37: =SUMIFS(Capacity!L:L,Capacity!$A:$A,Summary_CDP,Capacity!$B:$B,IF($B$30="NEM","*",$B$30),Capacity!$C:$C,$H37) -> 8391.2137 | Q37: =SUMIFS(Capacity!M:M,Capacity!$A:$A,Summary_CDP,Capacity!$B:$B,IF($B$30="NEM","*",$B$30),Capacity!$C:$C,$H37) -> 8391.2137 | R37: =SUMIFS(Capacity!N:N,Capacity!$A:$A,Summary_CDP,Capacity!$B:$B,IF($B$30="NEM","*",$B$30),Capacity!$C:$C,$H37) -> 8114.3537 | S37: =SUMIFS(Capacity!O:O,Capacity!$A:$A,Summary_CDP,Capacity!$B:$B,IF($B$30="NEM","*",$B$30),Capacity!$C:$C,$H37) -> 7652.3537 | T37: =SUMIFS(Capacity!P:P,Capacity!$A:$A,Summary_CDP,Capacity!$B:$B,IF($B$30="NEM","*",$B$30),Capacity!$C:$C,$H37) -> 7535.3537 | U37: =SUMIFS(Capacity!Q:Q,Capacity!$A:$A,Summary_CDP,Capacity!$B:$B,IF($B$30="NEM","*",$B$30),Capacity!$C:$C,$H37) -> 7405.3537 | V37: =SUMIFS(Capacity!R:R,Capacity!$A:$A,Summary_CDP,Capacity!$B:$B,IF($B$30="NEM","*",$B$30),Capacity!$C:$C,$H37) -> 7405.3537 | W37: =SUMIFS(Capacity!S:S,Capacity!$A:$A,Summary_CDP,Capacity!$B:$B,IF($B$30="NEM","*",$B$30),Capacity!$C:$C,$H37) -> 7405.3537 | X37: =SUMIFS(Capacity!T:T,Capacity!$A:$A,Summary_CDP,Capacity!$B:$B,IF($B$30="NEM","*",$B$30),Capacity!$C:$C,$H37) -> 9269.5644 | Y37: =SUMIFS(Capacity!U:U,Capacity!$A:$A,Summary_CDP,Capacity!$B:$B,IF($B$30="NEM","*",$B$30),Capacity!$C:$C,$H37) -> 8829.5644 | Z37: =SUMIFS(Capacity!V:V,Capacity!$A:$A,Summary_CDP,Capacity!$B:$B,IF($B$30="NEM","*",$B$30),Capacity!$C:$C,$H37) -> 8709.5644 | AA37: =SUMIFS(Capacity!W:W,Capacity!$A:$A,Summary_CDP,Capacity!$B:$B,IF($B$30="NEM","*",$B$30),Capacity!$C:$C,$H37) -> 8900.6327 | AB37: =SUMIFS(Capacity!X:X,Capacity!$A:$A,Summary_CDP,Capacity!$B:$B,IF($B$30="NEM","*",$B$30),Capacity!$C:$C,$H37) -> 8806.6327 | AC37: =SUMIFS(Capacity!Y:Y,Capacity!$A:$A,Summary_CDP,Capacity!$B:$B,IF($B$30="NEM","*",$B$30),Capacity!$C:$C,$H37) -> 12156.547 | AD37: =SUMIFS(Capacity!Z:Z,Capacity!$A:$A,Summary_CDP,Capacity!$B:$B,IF($B$30="NEM","*",$B$30),Capacity!$C:$C,$H37) -> 11386.989 | AE37: =SUMIFS(Capacity!AA:AA,Capacity!$A:$A,Summary_CDP,Capacity!$B:$B,IF($B$30="NEM","*",$B$30),Capacity!$C:$C,$H37) -> 11386.989 | AF37: =SUMIFS(Capacity!AB:AB,Capacity!$A:$A,Summary_CDP,Capacity!$B:$B,IF($B$30="NEM","*",$B$30),Capacity!$C:$C,$H37) -> 10683.989 | AG37: =SUMIFS(Capacity!AC:AC,Capacity!$A:$A,Summary_CDP,Capacity!$B:$B,IF($B$30="NEM","*",$B$30),Capacity!$C:$C,$H37) -> 10099.989 | AH37: =SUMIFS(Capacity!AD:AD,Capacity!$A:$A,Summary_CDP,Capacity!$B:$B,IF($B$30="NEM","*",$B$30),Capacity!$C:$C,$H37) -> 10099.989 | AI37: =SUMIFS(Capacity!AE:AE,Capacity!$A:$A,Summary_CDP,Capacity!$B:$B,IF($B$30="NEM","*",$B$30),Capacity!$C:$C,$H37) -> 11825.917 | AJ37: =SUMIFS(Capacity!AF:AF,Capacity!$A:$A,Summary_CDP,Capacity!$B:$B,IF($B$30="NEM","*",$B$30),Capacity!$C:$C,$H37) -> 11421.917
H38: Hydrogen Turbine | I38: =SUMIFS(Capacity!E:E,Capacity!$A:$A,Summary_CDP,Capacity!$B:$B,IF($B$30="NEM","*",$B$30),Capacity!$C:$C,$H38) -> 0 | J38: =SUMIFS(Capacity!F:F,Capacity!$A:$A,Summary_CDP,Capacity!$B:$B,IF($B$30="NEM","*",$B$30),Capacity!$C:$C,$H38) -> 0 | K38: =SUMIFS(Capacity!G:G,Capacity!$A:$A,Summary_CDP,Capacity!$B:$B,IF($B$30="NEM","*",$B$30),Capacity!$C:$C,$H38) -> 0 | L38: =SUMIFS(Capacity!H:H,Capacity!$A:$A,Summary_CDP,Capacity!$B:$B,IF($B$30="NEM","*",$B$30),Capacity!$C:$C,$H38) -> 0 | M38: =SUMIFS(Capacity!I:I,Capacity!$A:$A,Summary_CDP,Capacity!$B:$B,IF($B$30="NEM","*",$B$30),Capacity!$C:$C,$H38) -> 0 | N38: =SUMIFS(Capacity!J:J,Capacity!$A:$A,Summary_CDP,Capacity!$B:$B,IF($B$30="NEM","*",$B$30),Capacity!$C:$C,$H38) -> 0 | O38: =SUMIFS(Capacity!K:K,Capacity!$A:$A,Summary_CDP,Capacity!$B:$B,IF($B$30="NEM","*",$B$30),Capacity!$C:$C,$H38) -> 0 | P38: =SUMIFS(Capacity!L:L,Capacity!$A:$A,Summary_CDP,Capacity!$B:$B,IF($B$30="NEM","*",$B$30),Capacity!$C:$C,$H38) -> 0 | Q38: =SUMIFS(Capacity!M:M,Capacity!$A:$A,Summary_CDP,Capacity!$B:$B,IF($B$30="NEM","*",$B$30),Capacity!$C:$C,$H38) -> 0 | R38: =SUMIFS(Capacity!N:N,Capacity!$A:$A,Summary_CDP,Capacity!$B:$B,IF($B$30="NEM","*",$B$30),Capacity!$C:$C,$H38) -> 0 | S38: =SUMIFS(Capacity!O:O,Capacity!$A:$A,Summary_CDP,Capacity!$B:$B,IF($B$30="NEM","*",$B$30),Capacity!$C:$C,$H38) -> 0 | T38: =SUMIFS(Capacity!P:P,Capacity!$A:$A,Summary_CDP,Capacity!$B:$B,IF($B$30="NEM","*",$B$30),Capacity!$C:$C,$H38) -> 0 | U38: =SUMIFS(Capacity!Q:Q,Capacity!$A:$A,Summary_CDP,Capacity!$B:$B,IF($B$30="NEM","*",$B$30),Capacity!$C:$C,$H38) -> 0 | V38: =SUMIFS(Capacity!R:R,Capacity!$A:$A,Summary_CDP,Capacity!$B:$B,IF($B$30="NEM","*",$B$30),Capacity!$C:$C,$H38) -> 0 | W38: =SUMIFS(Capacity!S:S,Capacity!$A:$A,Summary_CDP,Capacity!$B:$B,IF($B$30="NEM","*",$B$30),Capacity!$C:$C,$H38) -> 0 | X38: =SUMIFS(Capacity!T:T,Capacity!$A:$A,Summary_CDP,Capacity!$B:$B,IF($B$30="NEM","*",$B$30),Capacity!$C:$C,$H38) -> 0 | Y38: =SUMIFS(Capacity!U:U,Capacity!$A:$A,Summary_CDP,Capacity!$B:$B,IF($B$30="NEM","*",$B$30),Capacity!$C:$C,$H38) -> 0 | Z38: =SUMIFS(Capacity!V:V,Capacity!$A:$A,Summary_CDP,Capacity!$B:$B,IF($B$30="NEM","*",$B$30),Capacity!$C:$C,$H38) -> 0 | AA38: =SUMIFS(Capacity!W:W,Capacity!$A:$A,Summary_CDP,Capacity!$B:$B,IF($B$30="NEM","*",$B$30),Capacity!$C:$C,$H38) -> 0 | AB38: =SUMIFS(Capacity!X:X,Capacity!$A:$A,Summary_CDP,Capacity!$B:$B,IF($B$30="NEM","*",$B$30),Capacity!$C:$C,$H38) -> 0 | AC38: =SUMIFS(Capacity!Y:Y,Capacity!$A:$A,Summary_CDP,Capacity!$B:$B,IF($B$30="NEM","*",$B$30),Capacity!$C:$C,$H38) -> 0 | AD38: =SUMIFS(Capacity!Z:Z,Capacity!$A:$A,Summary_CDP,Capacity!$B:$B,IF($B$30="NEM","*",$B$30),Capacity!$C:$C,$H38) -> 0 | AE38: =SUMIFS(Capacity!AA:AA,Capacity!$A:$A,Summary_CDP,Capacity!$B:$B,IF($B$30="NEM","*",$B$30),Capacity!$C:$C,$H38) -> 0 | AF38: =SUMIFS(Capacity!AB:AB,Capacity!$A:$A,Summary_CDP,Capacity!$B:$B,IF($B$30="NEM","*",$B$30),Capacity!$C:$C,$H38) -> 0 | AG38: =SUMIFS(Capacity!AC:AC,Capacity!$A:$A,Summary_CDP,Capacity!$B:$B,IF($B$30="NEM","*",$B$30),Capacity!$C:$C,$H38) -> 0 | AH38: =SUMIFS(Capacity!AD:AD,Capacity!$A:$A,Summary_CDP,Capacity!$B:$B,IF($B$30="NEM","*",$B$30),Capacity!$C:$C,$H38) -> 0 | AI38: =SUMIFS(Capacity!AE:AE,Capacity!$A:$A,Summary_CDP,Capacity!$B:$B,IF($B$30="NEM","*",$B$30),Capacity!$C:$C,$H38) -> 8612.6106 | AJ38: =SUMIFS(Capacity!AF:AF,Capacity!$A:$A,Summary_CDP,Capacity!$B:$B,IF($B$30="NEM","*",$B$30),Capacity!$C:$C,$H38) -> 8612.6106
H39: Hydro | I39: =SUMIFS(Capacity!E:E,Capacity!$A:$A,Summary_CDP,Capacity!$B:$B,IF($B$30="NEM","*",$B$30),Capacity!$C:$C,$H39) -> 6818.12 | J39: =SUMIFS(Capacity!F:F,Capacity!$A:$A,Summary_CDP,Capacity!$B:$B,IF($B$30="NEM","*",$B$30),Capacity!$C:$C,$H39) -> 6818.12 | K39: =SUMIFS(Capacity!G:G,Capacity!$A:$A,Summary_CDP,Capacity!$B:$B,IF($B$30="NEM","*",$B$30),Capacity!$C:$C,$H39) -> 6818.12 | L39: =SUMIFS(Capacity!H:H,Capacity!$A:$A,Summary_CDP,Capacity!$B:$B,IF($B$30="NEM","*",$B$30),Capacity!$C:$C,$H39) -> 6818.12 | M39: =SUMIFS(Capacity!I:I,Capacity!$A:$A,Summary_CDP,Capacity!$B:$B,IF($B$30="NEM","*",$B$30),Capacity!$C:$C,$H39) -> 6818.12 | N39: =SUMIFS(Capacity!J:J,Capacity!$A:$A,Summary_CDP,Capacity!$B:$B,IF($B$30="NEM","*",$B$30),Capacity!$C:$C,$H39) -> 6818.12 | O39: =SUMIFS(Capacity!K:K,Capacity!$A:$A,Summary_CDP,Capacity!$B:$B,IF($B$30="NEM","*",$B$30),Capacity!$C:$C,$H39) -> 7208.12 | P39: =SUMIFS(Capacity!L:L,Capacity!$A:$A,Summary_CDP,Capacity!$B:$B,IF($B$30="NEM","*",$B$30),Capacity!$C:$C,$H39) -> 7208.12 | Q39: =SUMIFS(Capacity!M:M,Capacity!$A:$A,Summary_CDP,Capacity!$B:$B,IF($B$30="NEM","*",$B$30),Capacity!$C:$C,$H39) -> 7208.12 | R39: =SUMIFS(Capacity!N:N,Capacity!$A:$A,Summary_CDP,Capacity!$B:$B,IF($B$30="NEM","*",$B$30),Capacity!$C:$C,$H39) -> 7208.12 | S39: =SUMIFS(Capacity!O:O,Capacity!$A:$A,Summary_CDP,Capacity!$B:$B,IF($B$30="NEM","*",$B$30),Capacity!$C:$C,$H39) -> 7208.12 | T39: =SUMIFS(Capacity!P:P,Capacity!$A:$A,Summary_CDP,Capacity!$B:$B,IF($B$30="NEM","*",$B$30),Capacity!$C:$C,$H39) -> 7208.12 | U39: =SUMIFS(Capacity!Q:Q,Capacity!$A:$A,Summary_CDP,Capacity!$B:$B,IF($B$30="NEM","*",$B$30),Capacity!$C:$C,$H39) -> 7208.12 | V39: =SUMIFS(Capacity!R:R,Capacity!$A:$A,Summary_CDP,Capacity!$B:$B,IF($B$30="NEM","*",$B$30),Capacity!$C:$C,$H39) -> 7208.12 | W39: =SUMIFS(Capacity!S:S,Capacity!$A:$A,Summary_CDP,Capacity!$B:$B,IF($B$30="NEM","*",$B$30),Capacity!$C:$C,$H39) -> 7121.72 | X39: =SUMIFS(Capacity!T:T,Capacity!$A:$A,Summary_CDP,Capacity!$B:$B,IF($B$30="NEM","*",$B$30),Capacity!$C:$C,$H39) -> 7121.72 | Y39: =SUMIFS(Capacity!U:U,Capacity!$A:$A,Summary_CDP,Capacity!$B:$B,IF($B$30="NEM","*",$B$30),Capacity!$C:$C,$H39) -> 7121.72 | Z39: =SUMIFS(Capacity!V:V,Capacity!$A:$A,Summary_CDP,Capacity!$B:$B,IF($B$30="NEM","*",$B$30),Capacity!$C:$C,$H39) -> 7121.72 | AA39: =SUMIFS(Capacity!W:W,Capacity!$A:$A,Summary_CDP,Capacity!$B:$B,IF($B$30="NEM","*",$B$30),Capacity!$C:$C,$H39) -> 7121.72 | AB39: =SUMIFS(Capacity!X:X,Capacity!$A:$A,Summary_CDP,Capacity!$B:$B,IF($B$30="NEM","*",$B$30),Capacity!$C:$C,$H39) -> 7055.72 | AC39: =SUMIFS(Capacity!Y:Y,Capacity!$A:$A,Summary_CDP,Capacity!$B:$B,IF($B$30="NEM","*",$B$30),Capacity!$C:$C,$H39) -> 7055.72 | AD39: =SUMIFS(Capacity!Z:Z,Capacity!$A:$A,Summary_CDP,Capacity!$B:$B,IF($B$30="NEM","*",$B$30),Capacity!$C:$C,$H39) -> 7055.72 | AE39: =SUMIFS(Capacity!AA:AA,Capacity!$A:$A,Summary_CDP,Capacity!$B:$B,IF($B$30="NEM","*",$B$30),Capacity!$C:$C,$H39) -> 7055.72 | AF39: =SUMIFS(Capacity!AB:AB,Capacity!$A:$A,Summary_CDP,Capacity!$B:$B,IF($B$30="NEM","*",$B$30),Capacity!$C:$C,$H39) -> 7055.72 | AG39: =SUMIFS(Capacity!AC:AC,Capacity!$A:$A,Summary_CDP,Capacity!$B:$B,IF($B$30="NEM","*",$B$30),Capacity!$C:$C,$H39) -> 7055.72 | AH39: =SUMIFS(Capacity!AD:AD,Capacity!$A:$A,Summary_CDP,Capacity!$B:$B,IF($B$30="NEM","*",$B$30),Capacity!$C:$C,$H39) -> 7055.72 | AI39: =SUMIFS(Capacity!AE:AE,Capacity!$A:$A,Summary_CDP,Capacity!$B:$B,IF($B$30="NEM","*",$B$30),Capacity!$C:$C,$H39) -> 7055.72 | AJ39: =SUMIFS(Capacity!AF:AF,Capacity!$A:$A,Summary_CDP,Capacity!$B:$B,IF($B$30="NEM","*",$B$30),Capacity!$C:$C,$H39) -> 7055.72
H40: Utility-scale Storage | I40: =SUMIFS(Capacity!E:E,Capacity!$A:$A,Summary_CDP,Capacity!$B:$B,IF($B$30="NEM","*",$B$30),Capacity!$C:$C,$H40) -> 1558.56 | J40: =SUMIFS(Capacity!F:F,Capacity!$A:$A,Summary_CDP,Capacity!$B:$B,IF($B$30="NEM","*",$B$30),Capacity!$C:$C,$H40) -> 1557.46 | K40: =SUMIFS(Capacity!G:G,Capacity!$A:$A,Summary_CDP,Capacity!$B:$B,IF($B$30="NEM","*",$B$30),Capacity!$C:$C,$H40) -> 3555.2419 | L40: =SUMIFS(Capacity!H:H,Capacity!$A:$A,Summary_CDP,Capacity!$B:$B,IF($B$30="NEM","*",$B$30),Capacity!$C:$C,$H40) -> 6481.0463 | M40: =SUMIFS(Capacity!I:I,Capacity!$A:$A,Summary_CDP,Capacity!$B:$B,IF($B$30="NEM","*",$B$30),Capacity!$C:$C,$H40) -> 9216.1182 | N40: =SUMIFS(Capacity!J:J,Capacity!$A:$A,Summary_CDP,Capacity!$B:$B,IF($B$30="NEM","*",$B$30),Capacity!$C:$C,$H40) -> 11055.301 | O40: =SUMIFS(Capacity!K:K,Capacity!$A:$A,Summary_CDP,Capacity!$B:$B,IF($B$30="NEM","*",$B$30),Capacity!$C:$C,$H40) -> 11057.244 | P40: =SUMIFS(Capacity!L:L,Capacity!$A:$A,Summary_CDP,Capacity!$B:$B,IF($B$30="NEM","*",$B$30),Capacity!$C:$C,$H40) -> 13439.528 | Q40: =SUMIFS(Capacity!M:M,Capacity!$A:$A,Summary_CDP,Capacity!$B:$B,IF($B$30="NEM","*",$B$30),Capacity!$C:$C,$H40) -> 13439.528 | R40: =SUMIFS(Capacity!N:N,Capacity!$A:$A,Summary_CDP,Capacity!$B:$B,IF($B$30="NEM","*",$B$30),Capacity!$C:$C,$H40) -> 13440.628 | S40: =SUMIFS(Capacity!O:O,Capacity!$A:$A,Summary_CDP,Capacity!$B:$B,IF($B$30="NEM","*",$B$30),Capacity!$C:$C,$H40) -> 13510.828 | T40: =SUMIFS(Capacity!P:P,Capacity!$A:$A,Summary_CDP,Capacity!$B:$B,IF($B$30="NEM","*",$B$30),Capacity!$C:$C,$H40) -> 13583.136 | U40: =SUMIFS(Capacity!Q:Q,Capacity!$A:$A,Summary_CDP,Capacity!$B:$B,IF($B$30="NEM","*",$B$30),Capacity!$C:$C,$H40) -> 16177.431 | V40: =SUMIFS(Capacity!R:R,Capacity!$A:$A,Summary_CDP,Capacity!$B:$B,IF($B$30="NEM","*",$B$30),Capacity!$C:$C,$H40) -> 17005.87 | W40: =SUMIFS(Capacity!S:S,Capacity!$A:$A,Summary_CDP,Capacity!$B:$B,IF($B$30="NEM","*",$B$30),Capacity!$C:$C,$H40) -> 18485.694 | X40: =SUMIFS(Capacity!T:T,Capacity!$A:$A,Summary_CDP,Capacity!$B:$B,IF($B$30="NEM","*",$B$30),Capacity!$C:$C,$H40) -> 18793.375 | Y40: =SUMIFS(Capacity!U:U,Capacity!$A:$A,Summary_CDP,Capacity!$B:$B,IF($B$30="NEM","*",$B$30),Capacity!$C:$C,$H40) -> 18792.275 | Z40: =SUMIFS(Capacity!V:V,Capacity!$A:$A,Summary_CDP,Capacity!$B:$B,IF($B$30="NEM","*",$B$30),Capacity!$C:$C,$H40) -> 20103.707 | AA40: =SUMIFS(Capacity!W:W,Capacity!$A:$A,Summary_CDP,Capacity!$B:$B,IF($B$30="NEM","*",$B$30),Capacity!$C:$C,$H40) -> 28248.188 | AB40: =SUMIFS(Capacity!X:X,Capacity!$A:$A,Summary_CDP,Capacity!$B:$B,IF($B$30="NEM","*",$B$30),Capacity!$C:$C,$H40) -> 28349.645 | AC40: =SUMIFS(Capacity!Y:Y,Capacity!$A:$A,Summary_CDP,Capacity!$B:$B,IF($B$30="NEM","*",$B$30),Capacity!$C:$C,$H40) -> 28840.233 | AD40: =SUMIFS(Capacity!Z:Z,Capacity!$A:$A,Summary_CDP,Capacity!$B:$B,IF($B$30="NEM","*",$B$30),Capacity!$C:$C,$H40) -> 30780.653 | AE40: =SUMIFS(Capacity!AA:AA,Capacity!$A:$A,Summary_CDP,Capacity!$B:$B,IF($B$30="NEM","*",$B$30),Capacity!$C:$C,$H40) -> 37455.491 | AF40: =SUMIFS(Capacity!AB:AB,Capacity!$A:$A,Summary_CDP,Capacity!$B:$B,IF($B$30="NEM","*",$B$30),Capacity!$C:$C,$H40) -> 37382.733 | AG40: =SUMIFS(Capacity!AC:AC,Capacity!$A:$A,Summary_CDP,Capacity!$B:$B,IF($B$30="NEM","*",$B$30),Capacity!$C:$C,$H40) -> 37047.052 | AH40: =SUMIFS(Capacity!AD:AD,Capacity!$A:$A,Summary_CDP,Capacity!$B:$B,IF($B$30="NEM","*",$B$30),Capacity!$C:$C,$H40) -> 47750.401 | AI40: =SUMIFS(Capacity!AE:AE,Capacity!$A:$A,Summary_CDP,Capacity!$B:$B,IF($B$30="NEM","*",$B$30),Capacity!$C:$C,$H40) -> 71709.968 | AJ40: =SUMIFS(Capacity!AF:AF,Capacity!$A:$A,Summary_CDP,Capacity!$B:$B,IF($B$30="NEM","*",$B$30),Capacity!$C:$C,$H40) -> 69913.132
H41: Coordinated DER Storage | I41: =SUMIFS(Capacity!E:E,Capacity!$A:$A,Summary_CDP,Capacity!$B:$B,IF($B$30="NEM","*",$B$30),Capacity!$C:$C,$H41) -> 366.507 | J41: =SUMIFS(Capacity!F:F,Capacity!$A:$A,Summary_CDP,Capacity!$B:$B,IF($B$30="NEM","*",$B$30),Capacity!$C:$C,$H41) -> 731.507 | K41: =SUMIFS(Capacity!G:G,Capacity!$A:$A,Summary_CDP,Capacity!$B:$B,IF($B$30="NEM","*",$B$30),Capacity!$C:$C,$H41) -> 1218.992 | L41: =SUMIFS(Capacity!H:H,Capacity!$A:$A,Summary_CDP,Capacity!$B:$B,IF($B$30="NEM","*",$B$30),Capacity!$C:$C,$H41) -> 1822.853 | M41: =SUMIFS(Capacity!I:I,Capacity!$A:$A,Summary_CDP,Capacity!$B:$B,IF($B$30="NEM","*",$B$30),Capacity!$C:$C,$H41) -> 2558.481 | N41: =SUMIFS(Capacity!J:J,Capacity!$A:$A,Summary_CDP,Capacity!$B:$B,IF($B$30="NEM","*",$B$30),Capacity!$C:$C,$H41) -> 3412.119 | O41: =SUMIFS(Capacity!K:K,Capacity!$A:$A,Summary_CDP,Capacity!$B:$B,IF($B$30="NEM","*",$B$30),Capacity!$C:$C,$H41) -> 4696.274 | P41: =SUMIFS(Capacity!L:L,Capacity!$A:$A,Summary_CDP,Capacity!$B:$B,IF($B$30="NEM","*",$B$30),Capacity!$C:$C,$H41) -> 5829.8005 | Q41: =SUMIFS(Capacity!M:M,Capacity!$A:$A,Summary_CDP,Capacity!$B:$B,IF($B$30="NEM","*",$B$30),Capacity!$C:$C,$H41) -> 7024.5443 | R41: =SUMIFS(Capacity!N:N,Capacity!$A:$A,Summary_CDP,Capacity!$B:$B,IF($B$30="NEM","*",$B$30),Capacity!$C:$C,$H41) -> 8398.683 | S41: =SUMIFS(Capacity!O:O,Capacity!$A:$A,Summary_CDP,Capacity!$B:$B,IF($B$30="NEM","*",$B$30),Capacity!$C:$C,$H41) -> 10091.142 | T41: =SUMIFS(Capacity!P:P,Capacity!$A:$A,Summary_CDP,Capacity!$B:$B,IF($B$30="NEM","*",$B$30),Capacity!$C:$C,$H41) -> 11935.595 | U41: =SUMIFS(Capacity!Q:Q,Capacity!$A:$A,Summary_CDP,Capacity!$B:$B,IF($B$30="NEM","*",$B$30),Capacity!$C:$C,$H41) -> 13875.121 | V41: =SUMIFS(Capacity!R:R,Capacity!$A:$A,Summary_CDP,Capacity!$B:$B,IF($B$30="NEM","*",$B$30),Capacity!$C:$C,$H41) -> 15894.635 | W41: =SUMIFS(Capacity!S:S,Capacity!$A:$A,Summary_CDP,Capacity!$B:$B,IF($B$30="NEM","*",$B$30),Capacity!$C:$C,$H41) -> 17933.751 | X41: =SUMIFS(Capacity!T:T,Capacity!$A:$A,Summary_CDP,Capacity!$B:$B,IF($B$30="NEM","*",$B$30),Capacity!$C:$C,$H41) -> 19983.078 | Y41: =SUMIFS(Capacity!U:U,Capacity!$A:$A,Summary_CDP,Capacity!$B:$B,IF($B$30="NEM","*",$B$30),Capacity!$C:$C,$H41) -> 21671.677 | Z41: =SUMIFS(Capacity!V:V,Capacity!$A:$A,Summary_CDP,Capacity!$B:$B,IF($B$30="NEM","*",$B$30),Capacity!$C:$C,$H41) -> 23318.225 | AA41: =SUMIFS(Capacity!W:W,Capacity!$A:$A,Summary_CDP,Capacity!$B:$B,IF($B$30="NEM","*",$B$30),Capacity!$C:$C,$H41) -> 24889.356 | AB41: =SUMIFS(Capacity!X:X,Capacity!$A:$A,Summary_CDP,Capacity!$B:$B,IF($B$30="NEM","*",$B$30),Capacity!$C:$C,$H41) -> 26447.73 | AC41: =SUMIFS(Capacity!Y:Y,Capacity!$A:$A,Summary_CDP,Capacity!$B:$B,IF($B$30="NEM","*",$B$30),Capacity!$C:$C,$H41) -> 28117.47 | AD41: =SUMIFS(Capacity!Z:Z,Capacity!$A:$A,Summary_CDP,Capacity!$B:$B,IF($B$30="NEM","*",$B$30),Capacity!$C:$C,$H41) -> 29806.333 | AE41: =SUMIFS(Capacity!AA:AA,Capacity!$A:$A,Summary_CDP,Capacity!$B:$B,IF($B$30="NEM","*",$B$30),Capacity!$C:$C,$H41) -> 31258.097 | AF41: =SUMIFS(Capacity!AB:AB,Capacity!$A:$A,Summary_CDP,Capacity!$B:$B,IF($B$30="NEM","*",$B$30),Capacity!$C:$C,$H41) -> 32733.875 | AG41: =SUMIFS(Capacity!AC:AC,Capacity!$A:$A,Summary_CDP,Capacity!$B:$B,IF($B$30="NEM","*",$B$30),Capacity!$C:$C,$H41) -> 34233.92 | AH41: =SUMIFS(Capacity!AD:AD,Capacity!$A:$A,Summary_CDP,Capacity!$B:$B,IF($B$30="NEM","*",$B$30),Capacity!$C:$C,$H41) -> 35763.291 | AI41: =SUMIFS(Capacity!AE:AE,Capacity!$A:$A,Summary_CDP,Capacity!$B:$B,IF($B$30="NEM","*",$B$30),Capacity!$C:$C,$H41) -> 37313.352 | AJ41: =SUMIFS(Capacity!AF:AF,Capacity!$A:$A,Summary_CDP,Capacity!$B:$B,IF($B$30="NEM","*",$B$30),Capacity!$C:$C,$H41) -> 37421.09
H42: Distributed Storage | I42: =SUMIFS(Capacity!E:E,Capacity!$A:$A,Summary_CDP,Capacity!$B:$B,IF($B$30="NEM","*",$B$30),Capacity!$C:$C,$H42) -> 1615.687 | J42: =SUMIFS(Capacity!F:F,Capacity!$A:$A,Summary_CDP,Capacity!$B:$B,IF($B$30="NEM","*",$B$30),Capacity!$C:$C,$H42) -> 2523.858 | K42: =SUMIFS(Capacity!G:G,Capacity!$A:$A,Summary_CDP,Capacity!$B:$B,IF($B$30="NEM","*",$B$30),Capacity!$C:$C,$H42) -> 3346.118 | L42: =SUMIFS(Capacity!H:H,Capacity!$A:$A,Summary_CDP,Capacity!$B:$B,IF($B$30="NEM","*",$B$30),Capacity!$C:$C,$H42) -> 4039.736 | M42: =SUMIFS(Capacity!I:I,Capacity!$A:$A,Summary_CDP,Capacity!$B:$B,IF($B$30="NEM","*",$B$30),Capacity!$C:$C,$H42) -> 4643.731 | N42: =SUMIFS(Capacity!J:J,Capacity!$A:$A,Summary_CDP,Capacity!$B:$B,IF($B$30="NEM","*",$B$30),Capacity!$C:$C,$H42) -> 5111.685 | O42: =SUMIFS(Capacity!K:K,Capacity!$A:$A,Summary_CDP,Capacity!$B:$B,IF($B$30="NEM","*",$B$30),Capacity!$C:$C,$H42) -> 5870.22 | P42: =SUMIFS(Capacity!L:L,Capacity!$A:$A,Summary_CDP,Capacity!$B:$B,IF($B$30="NEM","*",$B$30),Capacity!$C:$C,$H42) -> 6883.914 | Q42: =SUMIFS(Capacity!M:M,Capacity!$A:$A,Summary_CDP,Capacity!$B:$B,IF($B$30="NEM","*",$B$30),Capacity!$C:$C,$H42) -> 7823.741 | R42: =SUMIFS(Capacity!N:N,Capacity!$A:$A,Summary_CDP,Capacity!$B:$B,IF($B$30="NEM","*",$B$30),Capacity!$C:$C,$H42) -> 8822.021 | S42: =SUMIFS(Capacity!O:O,Capacity!$A:$A,Summary_CDP,Capacity!$B:$B,IF($B$30="NEM","*",$B$30),Capacity!$C:$C,$H42) -> 10032.986 | T42: =SUMIFS(Capacity!P:P,Capacity!$A:$A,Summary_CDP,Capacity!$B:$B,IF($B$30="NEM","*",$B$30),Capacity!$C:$C,$H42) -> 11279.352 | U42: =SUMIFS(Capacity!Q:Q,Capacity!$A:$A,Summary_CDP,Capacity!$B:$B,IF($B$30="NEM","*",$B$30),Capacity!$C:$C,$H42) -> 12411.971 | V42: =SUMIFS(Capacity!R:R,Capacity!$A:$A,Summary_CDP,Capacity!$B:$B,IF($B$30="NEM","*",$B$30),Capacity!$C:$C,$H42) -> 13450.545 | W42: =SUMIFS(Capacity!S:S,Capacity!$A:$A,Summary_CDP,Capacity!$B:$B,IF($B$30="NEM","*",$B$30),Capacity!$C:$C,$H42) -> 14351.891 | X42: =SUMIFS(Capacity!T:T,Capacity!$A:$A,Summary_CDP,Capacity!$B:$B,IF($B$30="NEM","*",$B$30),Capacity!$C:$C,$H42) -> 15102.709 | Y42: =SUMIFS(Capacity!U:U,Capacity!$A:$A,Summary_CDP,Capacity!$B:$B,IF($B$30="NEM","*",$B$30),Capacity!$C:$C,$H42) -> 15417.929 | Z42: =SUMIFS(Capacity!V:V,Capacity!$A:$A,Summary_CDP,Capacity!$B:$B,IF($B$30="NEM","*",$B$30),Capacity!$C:$C,$H42) -> 15594.936 | AA42: =SUMIFS(Capacity!W:W,Capacity!$A:$A,Summary_CDP,Capacity!$B:$B,IF($B$30="NEM","*",$B$30),Capacity!$C:$C,$H42) -> 15616.079 | AB42: =SUMIFS(Capacity!X:X,Capacity!$A:$A,Summary_CDP,Capacity!$B:$B,IF($B$30="NEM","*",$B$30),Capacity!$C:$C,$H42) -> 15610.974 | AC42: =SUMIFS(Capacity!Y:Y,Capacity!$A:$A,Summary_CDP,Capacity!$B:$B,IF($B$30="NEM","*",$B$30),Capacity!$C:$C,$H42) -> 15555.227 | AD42: =SUMIFS(Capacity!Z:Z,Capacity!$A:$A,Summary_CDP,Capacity!$B:$B,IF($B$30="NEM","*",$B$30),Capacity!$C:$C,$H42) -> 15481.949 | AE42: =SUMIFS(Capacity!AA:AA,Capacity!$A:$A,Summary_CDP,Capacity!$B:$B,IF($B$30="NEM","*",$B$30),Capacity!$C:$C,$H42) -> 15387.778 | AF42: =SUMIFS(Capacity!AB:AB,Capacity!$A:$A,Summary_CDP,Capacity!$B:$B,IF($B$30="NEM","*",$B$30),Capacity!$C:$C,$H42) -> 15277.058 | AG42: =SUMIFS(Capacity!AC:AC,Capacity!$A:$A,Summary_CDP,Capacity!$B:$B,IF($B$30="NEM","*",$B$30),Capacity!$C:$C,$H42) -> 15144.979 | AH42: =SUMIFS(Capacity!AD:AD,Capacity!$A:$A,Summary_CDP,Capacity!$B:$B,IF($B$30="NEM","*",$B$30),Capacity!$C:$C,$H42) -> 15000.321 | AI42: =SUMIFS(Capacity!AE:AE,Capacity!$A:$A,Summary_CDP,Capacity!$B:$B,IF($B$30="NEM","*",$B$30),Capacity!$C:$C,$H42) -> 14832.36 | AJ42: =SUMIFS(Capacity!AF:AF,Capacity!$A:$A,Summary_CDP,Capacity!$B:$B,IF($B$30="NEM","*",$B$30),Capacity!$C:$C,$H42) -> 14832.36
